{"name": "Ошибка при попытке получить данные заказа без или по неверному трек-номеру", "status": "passed", "description": "Ошибка при попытке получить данные заказа без или по неверному\n        трек-номеру.", "steps": [{"name": "Получение заказа по трек-номеру.", "status": "passed", "parameters": [{"name": "track", "value": "0"}], "start": 1733420388558, "stop": 1733420388659}], "parameters": [{"name": "track", "value": "0"}, {"name": "expected", "value": "(404, 'Заказ не найден')"}], "start": 1733420388558, "stop": 1733420388660, "uuid": "6530f006-27af-4f2a-8cd9-01d3b99b60a5", "historyId": "e400a2fce6f9f785a0aab6bc7e3e6e40", "testCaseId": "9e3242c7a012519dd2d3dee5a0b56136", "fullName": "tests.orders.test_orders_get.TestOrdersGet#test_get_order_no_or_wrong_track_number_error", "labels": [{"name": "parentSuite", "value": "tests.orders"}, {"name": "suite", "value": "test_orders_get"}, {"name": "subSuite", "value": "TestOrdersGet"}, {"name": "host", "value": "ZenBook"}, {"name": "thread", "value": "14132-MainThread"}, {"name": "framework", "value": "pytest"}, {"name": "language", "value": "cpython3"}, {"name": "package", "value": "tests.orders.test_orders_get"}]}